Workbook

Sheet Data
D1: Gulf | F1: In port | H1: Loaded | J1: Due | K1: PNW | P1: Vancouver
C2: Loading | D2: Waiting to | E2: In Port | F2: 4-year | G2: Loaded | H2: prior | I2: Due | J2: 10-days | L2: Waiting to | M2: In Port | N2: Loaded | O2: Due | P2: In Port | Q2: Loaded | R2: Due | T2: In Port | U2: Loaded
A3: Date | D3: load | F3: average | G3: 7-Days | H3: 4-year avg | I3: 10-days | J3: prior 4-yr avg | K3: Loading | L3: load | N3: 7-Days | O3: 10-days | Q3: 7-Days | R3: 10-days | S3: Week #
A4: 34703 | B4: 01/04/1995 | E4: 39 | G4: 58 | I4: 62 | S4: 1
A5: 34710 | B5: 01/11/1995 | E5: 36 | G5: 64 | I5: 72 | S5: 2
A6: 34717 | B6: 01/18/1995 | E6: 40 | G6: 60 | I6: 73 | S6: 3
A7: 34724 | B7: 01/25/1995 | E7: 41 | G7: 59 | I7: 63 | S7: 4
A8: 34731 | B8: 02/01/1995 | E8: 36 | G8: 62 | I8: 79 | S8: 5
A9: 34738 | B9: 02/08/1995 | E9: 42 | G9: 59 | I9: 78 | S9: 6
A10: 34745 | B10: 02/15/1995 | E10: 42 | G10: na | I10: na | S10: 7
A11: 34752 | B11: 02/22/1995 | E11: 32 | G11: 58 | I11: 73 | S11: 8
A12: 34759 | B12: 03/01/1995 | E12: 38 | G12: 56 | I12: 72 | S12: 9
A13: 34766 | B13: 03/08/1995 | E13: 35 | G13: 58 | I13: 77 | S13: 10
A14: 34773 | B14: 03/15/1995 | E14: 32 | G14: 50 | I14: 77 | S14: 11
A15: 34780 | B15: 03/22/1995 | E15: 31 | G15: 50 | I15: 83 | S15: 12
A16: 34787 | B16: 03/29/1995 | E16: 32 | G16: 44 | I16: 90 | S16: 13
A17: 34794 | B17: 04/05/1995 | E17: 29 | G17: 47 | I17: 77 | S17: 14
A18: 34801 | B18: 04/12/1995 | E18: 29 | G18: na | I18: na | S18: 15
A19: 34808 | B19: 04/19/1995 | E19: 27 | G19: 47 | I19: 69 | S19: 16
A20: 34815 | B20: 04/26/1995 | E20: 19 | G20: 37 | I20: 48 | S20: 17
A21: 34822 | B21: 05/03/1995 | E21: 24 | G21: 48 | I21: 48 | S21: 18
A22: 34829 | B22: 05/10/1995 | E22: 24 | G22: na | I22: na | S22: 19
A23: 34836 | B23: 05/17/1995 | E23: 26 | G23: 43 | I23: 59 | S23: 20
A24: 34843 | B24: 05/24/1995 | E24: 23 | G24: 53 | I24: 49 | S24: 21
A25: 34850 | B25: 05/31/1995 | E25: 30 | G25: 45 | I25: 42 | S25: 22
A26: 34857 | B26: 06/07/1995 | E26: 26 | G26: 37 | I26: 37 | S26: 23
A27: 34864 | B27: 06/14/1995 | E27: 28 | G27: 22 | I27: 31 | S27: 24
A28: 34871 | B28: 06/21/1995 | E28: 27 | G28: 30 | I28: 38 | S28: 25
A29: 34878 | B29: 06/28/1995 | E29: 26 | G29: 41 | I29: 52 | S29: 26
A30: 34885 | B30: 07/05/1995 | E30: 24 | G30: 40 | I30: 50 | S30: 27
A31: 34892 | B31: 07/12/1995 | E31: 17 | G31: 38 | I31: 56 | S31: 28
A32: 34899 | B32: 07/19/1995 | E32: 23 | G32: 44 | I32: 60 | S32: 29
A33: 34906 | B33: 07/26/1995 | E33: 24 | G33: 40 | I33: 67 | S33: 30
A34: 34913 | B34: 08/02/1995 | E34: 25 | G34: 48 | I34: 70 | S34: 31
... A54: 35053 | B54: 12/20/1995 | E54: 39 | G54: 39 | I54: 71 | S54: 51
A55: 35060 | B55: 12/27/1995 | E55: 32 | G55: 49 | I55: 66 | S55: 52 | T55: 31.358491 | U55: 45.933333
A56: 35067 | B56: 01/03/1996 | E56: 34 | G56: 40 | I56: 83 | S56: 1
A57: 35075 | B57: 01/11/1996 | E57: 37 | G57: 56 | I57: 75 | S57: 2
A58: 35081 | B58: 01/17/1996 | E58: 38 | G58: 52 | I58: 81 | S58: 3
A59: 35088 | B59: 01/24/1996 | E59: 30 | G59: 55 | I59: 88 | S59: 4
...

Sheet New  Table 19
A1: Table 19
A2: Weekly port region grain ocean vessel activity (number of vessels)
A3: Date | B3: Gulf | E3: Pacific Northwest
B5: In port | C5: Loaded 7-days | D5: Due next 10-days | E5: In port
A7: =Data!A1662 -> 46310 | B7: =Data!E1662 -> 24 | C7: =Data!G1662 -> 31 | D7: =Data!I1662 -> 45 | E7: =Data!M1662 -> 18
A8: =Data!A1661 -> 46303 | B8: =Data!E1661 -> 27 | C8: =Data!G1661 -> 28 | D8: =Data!I1661 -> 46 | E8: =Data!M1661 -> 17
A9: 2025 range | B9: (12…40) | C9: (11…37) | D9: (26…55) | E9: (5…25)
A10: 2025 average | B10: 28 | C10: 28 | D10: 45 | E10: 13
A11: Source: USDA, Agricultural Marketing Service.

Sheet Figure 19 Redesigned
B43: Alt Text:
B45: This figure depicts bar chats representing grain vessel loading activity for the ocean-going vessels in the U.S. Gulf

Sheet Figure 19 table
D5: Week ending 10/15/26, number of vessels | E5: Loaded | F5: Due
D6: Change from last year | E6: 0.033 | F6: -0.043
D7: Change from 4-year average | E7: -0.031 | F7: 0.047
